Workbook
Name Prezzo: 'Inputs'!$B$5
Name PrezzoBase: 'Inputs'!$B$6
Name OffertaMinima: 'Inputs'!$B$7
Name Cauzione_pct: 'Inputs'!$B$8
Name Registro_pct: 'Inputs'!$B$9
Name ImposteFisse: 'Inputs'!$B$10
Name SpeseTrasf: 'Inputs'!$B$11
Name ArretratiCond: 'Inputs'!$B$12
Name CondAnnuo: 'Inputs'!$B$13
Name ImuAnnua: 'Inputs'!$B$14
Name UtenzeMese: 'Inputs'!$B$15
Name MqAlloggio: 'Inputs'!$B$16
Name MqComm: 'Inputs'!$B$17
Name LavoriMq: 'Inputs'!$B$18
Name Imprevisti_pct: 'Inputs'!$B$19
Name Regolarizz: 'Inputs'!$B$20
Name Vendita_pct: 'Inputs'!$B$21
Name Ires_pct: 'Inputs'!$B$22
Name Accessori: 'Inputs'!$B$23
Name ValorePerizia: 'Inputs'!$B$24
Name Margine_obj: 'Inputs'!$B$25
Name Irr_obj: 'Inputs'!$B$26
Name Moltiplicatore: 'Inputs'!$B$27
Name DataAgg: 'Inputs'!$B$28
Name MeseSaldo: 'Inputs'!$B$29
Name MesiDecreto: 'Inputs'!$B$30
Name MesiLavori: 'Inputs'!$B$31
Name Sponsor_cap: 'Inputs'!$B$32
Name Pref_pct: 'Inputs'!$B$33
Name Sponsor_split: 'Inputs'!$B$34
Name MesiGriglia: 'Inputs'!$B$35
Name NumScenari: 'Inputs'!$B$36
Name Scenario: 'Inputs'!$B$39
Name UscitaMq: 'Inputs'!$B$41
Name MesiLiberazione: 'Inputs'!$B$42
Name Ripristino: 'Inputs'!$B$43
Name MesiVendita: 'Inputs'!$B$44
Name MeseDecreto: 'Inputs'!$B$47
Name MeseLiber: 'Inputs'!$B$48
Name MeseLavoriIni: 'Inputs'!$B$49
Name MeseLavoriFine: 'Inputs'!$B$50
Name MeseVendita: 'Inputs'!$B$51
Name Arv: 'Inputs'!$B$52
Name LavoriTot: 'Inputs'!$B$53
Name TassoMese: 'Inputs'!$B$54
Name ErroriTot: 'Checks'!$B$21
Name AvvisiTot: 'Checks'!$B$22

Sheet Cover
A1: Quantum Re - Fix & flip, lotto PVP 4635523
A2: Via Del Carso 2-4-6, Arluno (MI), zona OMI B1. Trilocale A/3 al 2 piano senza ascensore, cantina e box 21 mq; edificio anni '70. RGE 1138/2025, asta 02/12/2026.
A3: Segni: entrate positive, uscite negative. IRR: mensile composto ((1+IRR)^12-1). Nessun debito: capitale proprio del club deal.
A5: Scenario attivo | C5: =CHOOSE(Scenario,"Base","Favorevole","Sfavorevole")
A6: Prezzo massimo d'offerta | C6: =Outputs!C21
A7: Vincolo che lega | C7: =Outputs!C22
A8: Margine all'offerta minima (84.600) | C8: =Outputs!C50
A9: Aggiudicazione attesa (base x moltiplicatore) | C9: =Outputs!C24
A10: Al prezzo offerto: margine sul costo | C10: =Outputs!C7
A11: Uscita minima per margine 30% (al prezzo offerto) | C11: =Outputs!C28
A12: Uscita per utile zero | C12: =Outputs!C29
A13: Capitale impegnato | C13: =Outputs!C8
A14: Errori nei controlli | C14: =ErroriTot
A15: Avvisi | C15: =AvvisiTot
A16: Al prezzo offerto: IRR ante imposte | C16: =Outputs!C9
A17: Da confermare prima di offrire: stato interno al sopralluogo, tempi di liberazione, assemblee condominiali recenti, regime fiscale, percentuale della cauzione.
A18: Fonti: avviso di vendita e perizia (PVP, RGE 1138/2025), OMI Agenzia Entrate 2026-1, storico QRE. Ipotesi in blu nel foglio Inputs.

Sheet Inputs
A1: Ipotesi e dati - Lotto PVP 4635523, via Del Carso 2-4-6, Arluno (RGE 1138/2025)
A2: Blu = dato o ipotesi inseriti a mano; nero = formula. Ogni riga dichiara la fonte.
A4: Voce | B4: Usato | C4: Unita' | D4: Fonte / stato
A5: Prezzo offerto (aggiudicazione) | B5: 112800 | C5: EUR | D5: Caso base = prezzo base dell'avviso. Variabile di decisione
A6: Prezzo base | B6: 112800 | C6: EUR | D6: Dato: avviso di vendita
A7: Offerta minima (75% della base) | B7: 84600 | C7: EUR | D7: Dato: avviso di vendita
A8: Cauzione versata con l'offerta | B8: 0.1 | C8: % prezzo | D8: IPOTESI: prassi 10%; il testo estratto dell'avviso non riporta la percentuale, verificarla
A9: Imposta di registro (societa') | B9: 0.09 | C9: % prezzo | D9: IPOTESI da verificare col parere fiscale (agevolazioni per imprese che rivendono, IVA)
A10: Ipotecaria + catastale | B10: 100 | C10: EUR | D10: Ipotesi: 50 + 50 EUR in misura fissa
A11: Compenso delegato e spese di trasferimento | B11: 2000 | C11: EUR | D11: IPOTESI; cancellazione gravami a carico della procedura (avviso)
A12: Spese condominiali arretrate (art. 63 disp. att. c.c.) | B12: 9350 | C12: EUR | D12: Dato: perizia (2 anni di ordinarie 6.700 + straordinarie deliberate 2.650)
A13: Spese condominiali ordinarie | B13: 3700 | C13: EUR/anno | D13: Dato: perizia (preventivo 2024-25, riscaldamento centralizzato compreso)
A14: IMU | B14: 744 | C14: EUR/anno | D14: Calcolo: rendite 355,06 + 62,90 x 1,05 x 160 x 10,6 per mille (aliquota di Arluno: IPOTESI)
A15: Utenze e assicurazione | B15: 80 | C15: EUR/mese | D15: IPOTESI
A16: Superficie alloggio | B16: 96 | C16: mq | D16: Dato: perizia, superficie lorda dell'appartamento
... A24: Valore dell'alloggio in perizia (senza box, prima delle decurtazioni) | B24: 147000 | C24: EUR | D24: Dato: perizia (98 mq x 1.500 EUR/mq); lotto 162.000, al netto delle decurtazioni 141.050
A25: Margine obiettivo sul costo | B25: 0.3 | D25: Soglia QRE
A26: IRR minimo annuo | B26: 0.12 | D26: Soglia QRE
A27: Aggiudicazione attesa / base (giudiziarie) | B27: 1.2 | D27: Storico QRE: 19 aste 2022-2026, mediana 1,20 (radar); per l'hinterland non calibrato
A28: Data di aggiudicazione | B28: 46358 | C28: data | D28: Dato: avviso di vendita
A29: Saldo prezzo (mesi dall'aggiudicazione) | B29: 4 | C29: mesi | D29: Dato: avviso, entro 120 giorni
A30: Dal saldo al decreto di trasferimento | B30: 2 | C30: mesi | D30: IPOTESI
A31: Durata lavori e regolarizzazioni | B31: 2 | C31: mesi | D31: IPOTESI
A32: Quota di capitale del promotore (QRE) | B32: 0.1 | D32: IPOTESI di struttura del club deal
A33: Rendimento preferenziale investitori | B33: 0.08 | C33: annuo | D33: IPOTESI di struttura del club deal
A34: Quota dell'utile residuo al promotore | B34: 0.3 | D34: IPOTESI di struttura del club deal
A35: Mesi coperti dalla griglia dei flussi | B35: 36 | C35: mesi | D35: Costante del modello: la vendita deve cadere entro
A36: Scenari implementati | B36: 3 | C36: n | D36: Costante del modello
A38: Scenari (driver incerti)
A39: Scenario attivo (1 Base, 2 Favorevole, 3 Sfavorevole) | B39: 1
A40: Driver | B40: Usato | C40: Unita' | D40: Base | E40: Favorevole | F40: Sfavorevole | G40: Motivo
A41: Valore di uscita | B41: =CHOOSE(Scenario,D41,E41,F41) | C41: EUR/mq | D41: 1550 | E41: 1700 | F41: 1400 | G41: OMI 2026-1 zona B1 abitazioni di tipo economico stato OTTIMO 1.450-1.700; agenzie di zona 1.570-1.670 (perizia); perizia 1.500 nello stato attuale
A42: Liberazione dopo il decreto (occupante senza titolo) | B42: =CHOOSE(Scenario,D42,E42,F42) | C42: mesi | D42: 1 | E42: 0 | F42: 4 | G42: Ordine di liberazione gia' emesso il 29/05/2026 (perizia); tempi del custode: IPOTESI
A43: Imprevisti su impianti e parti comuni (edificio anni '70) | B43: =CHOOSE(Scenario,D43,E43,F43) | C43: EUR | D43: 3000 | E43: 0 | F43: 12000 | G43: IPOTESI: riscaldamento centralizzato e straordinarie non ancora deliberate
A44: Commercializzazione e rogito | B44: =CHOOSE(Scenario,D44,E44,F44) | C44: mesi | D44: 5 | E44: 3 | F44: 8 | G44: IPOTESI
A46: Calendario derivato
A47: Mese del decreto | B47: =MeseSaldo+MesiDecreto
A48: Mese della liberazione | B48: =MeseDecreto+MesiLiberazione
A49: Inizio lavori | B49: =MeseLiber+1
A50: Fine lavori | B50: =MeseLavoriIni+MesiLavori-1
...

Sheet CF
A1: Flussi di cassa mensili (entrate +, uscite -), senza debito: capitale del club deal
A3: Mese | B3: n | E3: =IF(ISNUMBER(D3),D3+1,0) | F3: =IF(ISNUMBER(E3),E3+1,0) | G3: =IF(ISNUMBER(F3),F3+1,0) | H3: =IF(ISNUMBER(G3),G3+1,0) | I3: =IF(ISNUMBER(H3),H3+1,0) | J3: =IF(ISNUMBER(I3),I3+1,0) | K3: =IF(ISNUMBER(J3),J3+1,0) | L3: =IF(ISNUMBER(K3),K3+1,0) | ... AO3: =IF(ISNUMBER(AN3),AN3+1,0)
A4: Data (fine mese) | B4: data | E4: =EOMONTH(DataAgg,E3) | F4: =EOMONTH(DataAgg,F3) | G4: =EOMONTH(DataAgg,G3) | H4: =EOMONTH(DataAgg,H3) | I4: =EOMONTH(DataAgg,I3) | J4: =EOMONTH(DataAgg,J3) | K4: =EOMONTH(DataAgg,K3) | L4: =EOMONTH(DataAgg,L3) | ... AO4: =EOMONTH(DataAgg,AO3)
A5: Flag saldo | B5: 1/0 | C5: =SUM(E5:AO5) | E5: =1*(E$3=MeseSaldo) | F5: =1*(F$3=MeseSaldo) | G5: =1*(G$3=MeseSaldo) | H5: =1*(H$3=MeseSaldo) | I5: =1*(I$3=MeseSaldo) | J5: =1*(J$3=MeseSaldo) | K5: =1*(K$3=MeseSaldo) | L5: =1*(L$3=MeseSaldo) | ... AO5: =1*(AO$3=MeseSaldo)
A6: Flag decreto | B6: 1/0 | C6: =SUM(E6:AO6) | E6: =1*(E$3=MeseDecreto) | F6: =1*(F$3=MeseDecreto) | G6: =1*(G$3=MeseDecreto) | H6: =1*(H$3=MeseDecreto) | I6: =1*(I$3=MeseDecreto) | J6: =1*(J$3=MeseDecreto) | K6: =1*(K$3=MeseDecreto) | L6: =1*(L$3=MeseDecreto) | ... AO6: =1*(AO$3=MeseDecreto)
A7: Flag possesso (decreto - vendita) | B7: 1/0 | C7: =SUM(E7:AO7) | E7: =1*(E$3>MeseDecreto)*(E$3<=MeseVendita) | F7: =1*(F$3>MeseDecreto)*(F$3<=MeseVendita) | G7: =1*(G$3>MeseDecreto)*(G$3<=MeseVendita) | H7: =1*(H$3>MeseDecreto)*(H$3<=MeseVendita) | I7: =1*(I$3>MeseDecreto)*(I$3<=MeseVendita) | J7: =1*(J$3>MeseDecreto)*(J$3<=MeseVendita) | K7: =1*(K$3>MeseDecreto)*(K$3<=MeseVendita) | L7: =1*(L$3>MeseDecreto)*(L$3<=MeseVendita) | ... AO7: =1*(AO$3>MeseDecreto)*(AO$3<=MeseVendita)
A8: Flag lavori | B8: 1/0 | C8: =SUM(E8:AO8) | E8: =1*(E$3>=MeseLavoriIni)*(E$3<=MeseLavoriFine) | F8: =1*(F$3>=MeseLavoriIni)*(F$3<=MeseLavoriFine) | G8: =1*(G$3>=MeseLavoriIni)*(G$3<=MeseLavoriFine) | H8: =1*(H$3>=MeseLavoriIni)*(H$3<=MeseLavoriFine) | I8: =1*(I$3>=MeseLavoriIni)*(I$3<=MeseLavoriFine) | J8: =1*(J$3>=MeseLavoriIni)*(J$3<=MeseLavoriFine) | K8: =1*(K$3>=MeseLavoriIni)*(K$3<=MeseLavoriFine) | L8: =1*(L$3>=MeseLavoriIni)*(L$3<=MeseLavoriFine) | ... AO8: =1*(AO$3>=MeseLavoriIni)*(AO$3<=MeseLavoriFine)
A9: Flag inizio lavori | B9: 1/0 | C9: =SUM(E9:AO9) | E9: =1*(E$3=MeseLavoriIni) | F9: =1*(F$3=MeseLavoriIni) | G9: =1*(G$3=MeseLavoriIni) | H9: =1*(H$3=MeseLavoriIni) | I9: =1*(I$3=MeseLavoriIni) | J9: =1*(J$3=MeseLavoriIni) | K9: =1*(K$3=MeseLavoriIni) | L9: =1*(L$3=MeseLavoriIni) | ... AO9: =1*(AO$3=MeseLavoriIni)
A10: Flag vendita | B10: 1/0 | C10: =SUM(E10:AO10) | E10: =1*(E$3=MeseVendita) | F10: =1*(F$3=MeseVendita) | G10: =1*(G$3=MeseVendita) | H10: =1*(H$3=MeseVendita) | I10: =1*(I$3=MeseVendita) | J10: =1*(J$3=MeseVendita) | K10: =1*(K$3=MeseVendita) | L10: =1*(L$3=MeseVendita) | ... AO10: =1*(AO$3=MeseVendita)
A12: Famiglia prezzo (lineare nel prezzo offerto)
A13: Cauzione | B13: EUR | C13: =SUM(E13:AO13) | E13: =-Cauzione_pct*Prezzo*1*(E$3=0) | F13: =-Cauzione_pct*Prezzo*1*(F$3=0) | G13: =-Cauzione_pct*Prezzo*1*(G$3=0) | H13: =-Cauzione_pct*Prezzo*1*(H$3=0) | I13: =-Cauzione_pct*Prezzo*1*(I$3=0) | J13: =-Cauzione_pct*Prezzo*1*(J$3=0) | K13: =-Cauzione_pct*Prezzo*1*(K$3=0) | L13: =-Cauzione_pct*Prezzo*1*(L$3=0) | ... AO13: =-Cauzione_pct*Prezzo*1*(AO$3=0)
A14: Saldo prezzo | B14: EUR | C14: =SUM(E14:AO14) | E14: =-(1-Cauzione_pct)*Prezzo*E$5 | F14: =-(1-Cauzione_pct)*Prezzo*F$5 | G14: =-(1-Cauzione_pct)*Prezzo*G$5 | H14: =-(1-Cauzione_pct)*Prezzo*H$5 | I14: =-(1-Cauzione_pct)*Prezzo*I$5 | J14: =-(1-Cauzione_pct)*Prezzo*J$5 | K14: =-(1-Cauzione_pct)*Prezzo*K$5 | L14: =-(1-Cauzione_pct)*Prezzo*L$5 | ... AO14: =-(1-Cauzione_pct)*Prezzo*AO$5
A15: Imposta di registro | B15: EUR | C15: =SUM(E15:AO15) | E15: =-Registro_pct*Prezzo*E$5 | F15: =-Registro_pct*Prezzo*F$5 | G15: =-Registro_pct*Prezzo*G$5 | H15: =-Registro_pct*Prezzo*H$5 | I15: =-Registro_pct*Prezzo*I$5 | J15: =-Registro_pct*Prezzo*J$5 | K15: =-Registro_pct*Prezzo*K$5 | L15: =-Registro_pct*Prezzo*L$5 | ... AO15: =-Registro_pct*Prezzo*AO$5
A16: Totale famiglia prezzo | B16: EUR | C16: =SUM(E16:AO16) | E16: =E13+E14+E15 | F16: =F13+F14+F15 | G16: =G13+G14+G15 | H16: =H13+H14+H15 | I16: =I13+I14+I15 | J16: =J13+J14+J15 | K16: =K13+K14+K15 | L16: =L13+L14+L15 | ... AO16: =AO13+AO14+AO15
A18: Altri costi
A19: Imposte fisse e spese di trasferimento | B19: EUR | C19: =SUM(E19:AO19) | E19: =-(ImposteFisse+SpeseTrasf)*E$5 | F19: =-(ImposteFisse+SpeseTrasf)*F$5 | G19: =-(ImposteFisse+SpeseTrasf)*G$5 | H19: =-(ImposteFisse+SpeseTrasf)*H$5 | I19: =-(ImposteFisse+SpeseTrasf)*I$5 | J19: =-(ImposteFisse+SpeseTrasf)*J$5 | K19: =-(ImposteFisse+SpeseTrasf)*K$5 | L19: =-(ImposteFisse+SpeseTrasf)*L$5 | ... AO19: =-(ImposteFisse+SpeseTrasf)*AO$5
A20: Arretrati condominiali | B20: EUR | C20: =SUM(E20:AO20) | E20: =-ArretratiCond*E$6 | F20: =-ArretratiCond*F$6 | G20: =-ArretratiCond*G$6 | H20: =-ArretratiCond*H$6 | I20: =-ArretratiCond*I$6 | J20: =-ArretratiCond*J$6 | K20: =-ArretratiCond*K$6 | L20: =-ArretratiCond*L$6 | ... AO20: =-ArretratiCond*AO$6
A21: Condominio ordinario | B21: EUR | C21: =SUM(E21:AO21) | E21: =-CondAnnuo/12*E$7 | F21: =-CondAnnuo/12*F$7 | G21: =-CondAnnuo/12*G$7 | H21: =-CondAnnuo/12*H$7 | I21: =-CondAnnuo/12*I$7 | J21: =-CondAnnuo/12*J$7 | K21: =-CondAnnuo/12*K$7 | L21: =-CondAnnuo/12*L$7 | ... AO21: =-CondAnnuo/12*AO$7
A22: IMU | B22: EUR | C22: =SUM(E22:AO22) | E22: =-ImuAnnua/12*E$7 | F22: =-ImuAnnua/12*F$7 | G22: =-ImuAnnua/12*G$7 | H22: =-ImuAnnua/12*H$7 | I22: =-ImuAnnua/12*I$7 | J22: =-ImuAnnua/12*J$7 | K22: =-ImuAnnua/12*K$7 | L22: =-ImuAnnua/12*L$7 | ... AO22: =-ImuAnnua/12*AO$7
A23: Utenze e assicurazione | B23: EUR | C23: =SUM(E23:AO23) | E23: =-UtenzeMese*E$7 | F23: =-UtenzeMese*F$7 | G23: =-UtenzeMese*G$7 | H23: =-UtenzeMese*H$7 | I23: =-UtenzeMese*I$7 | J23: =-UtenzeMese*J$7 | K23: =-UtenzeMese*K$7 | L23: =-UtenzeMese*L$7 | ... AO23: =-UtenzeMese*AO$7
A24: Sanatoria e catasto | B24: EUR | C24: =SUM(E24:AO24) | E24: =-Regolarizz*E$9 | F24: =-Regolarizz*F$9 | G24: =-Regolarizz*G$9 | H24: =-Regolarizz*H$9 | I24: =-Regolarizz*I$9 | J24: =-Regolarizz*J$9 | K24: =-Regolarizz*K$9 | L24: =-Regolarizz*L$9 | ... AO24: =-Regolarizz*AO$9
A25: Imprevisti su impianti e parti comuni | B25: EUR | C25: =SUM(E25:AO25) | E25: =-Ripristino/MAX(1,MesiLavori)*E$8 | F25: =-Ripristino/MAX(1,MesiLavori)*F$8 | G25: =-Ripristino/MAX(1,MesiLavori)*G$8 | H25: =-Ripristino/MAX(1,MesiLavori)*H$8 | I25: =-Ripristino/MAX(1,MesiLavori)*I$8 | J25: =-Ripristino/MAX(1,MesiLavori)*J$8 | K25: =-Ripristino/MAX(1,MesiLavori)*K$8 | L25: =-Ripristino/MAX(1,MesiLavori)*L$8 | ... AO25: =-Ripristino/MAX(1,MesiLavori)*AO$8
A26: Lavori di finitura | B26: EUR | C26: =SUM(E26:AO26) | E26: =-LavoriTot/MAX(1,MesiLavori)*E$8 | F26: =-LavoriTot/MAX(1,MesiLavori)*F$8 | G26: =-LavoriTot/MAX(1,MesiLavori)*G$8 | H26: =-LavoriTot/MAX(1,MesiLavori)*H$8 | I26: =-LavoriTot/MAX(1,MesiLavori)*I$8 | J26: =-LavoriTot/MAX(1,MesiLavori)*J$8 | K26: =-LavoriTot/MAX(1,MesiLavori)*K$8 | L26: =-LavoriTot/MAX(1,MesiLavori)*L$8 | ... AO26: =-LavoriTot/MAX(1,MesiLavori)*AO$8
A27: Totale altri costi | B27: EUR | C27: =SUM(E27:AO27) | E27: =SUM(E19:E26) | F27: =SUM(F19:F26) | G27: =SUM(G19:G26) | H27: =SUM(H19:H26) | I27: =SUM(I19:I26) | J27: =SUM(J19:J26) | K27: =SUM(K19:K26) | L27: =SUM(L19:L26) | ... AO27: =SUM(AO19:AO26)
A29: Vendita
A30: Prezzo di vendita | B30: EUR | C30: =SUM(E30:AO30) | E30: =Arv*E$10 | F30: =Arv*F$10 | G30: =Arv*G$10 | H30: =Arv*H$10 | I30: =Arv*I$10 | J30: =Arv*J$10 | K30: =Arv*K$10 | L30: =Arv*L$10 | ... AO30: =Arv*AO$10
A31: Costi di vendita | B31: EUR | C31: =SUM(E31:AO31) | E31: =-Vendita_pct*Arv*E$10 | F31: =-Vendita_pct*Arv*F$10 | G31: =-Vendita_pct*Arv*G$10 | H31: =-Vendita_pct*Arv*H$10 | I31: =-Vendita_pct*Arv*I$10 | J31: =-Vendita_pct*Arv*J$10 | K31: =-Vendita_pct*Arv*K$10 | L31: =-Vendita_pct*Arv*L$10 | ... AO31: =-Vendita_pct*Arv*AO$10
A32: Totale vendita netta | B32: EUR | C32: =SUM(E32:AO32) | E32: =E30+E31 | F32: =F30+F31 | G32: =G30+G31 | H32: =H30+H31 | I32: =I30+I31 | J32: =J30+J31 | K32: =K30+K31 | L32: =L30+L31 | ... AO32: =AO30+AO31
A34: Flusso di cassa ante imposte | B34: EUR | C34: =SUM(E34:AO34) | E34: =E16+E27+E32 | F34: =F16+F27+F32 | G34: =G16+G27+G32 | H34: =H16+H27+H32 | I34: =I16+I27+I32 | J34: =J16+J27+J32 | K34: =K16+K27+K32 | L34: =L16+L27+L32 | ... AO34: =AO16+AO27+AO32
A35: Cumulato | B35: EUR | E35: =IF(ISNUMBER(D35),D35,0)+E34 | F35: =IF(ISNUMBER(E35),E35,0)+F34 | G35: =IF(ISNUMBER(F35),F35,0)+G34 | H35: =IF(ISNUMBER(G35),G35,0)+H34 | I35: =IF(ISNUMBER(H35),H35,0)+I34 | J35: =IF(ISNUMBER(I35),I35,0)+J34 | K35: =IF(ISNUMBER(J35),J35,0)+K34 | L35: =IF(ISNUMBER(K35),K35,0)+L34 | ... AO35: =IF(ISNUMBER(AN35),AN35,0)+AO34
A36: IRES sull'utile (alla vendita) | B36: EUR | C36: =SUM(E36:AO36) | E36: =-Ires_pct*MAX(0,$C$34)*E$10 | F36: =-Ires_pct*MAX(0,$C$34)*F$10 | G36: =-Ires_pct*MAX(0,$C$34)*G$10 | H36: =-Ires_pct*MAX(0,$C$34)*H$10 | I36: =-Ires_pct*MAX(0,$C$34)*I$10 | J36: =-Ires_pct*MAX(0,$C$34)*J$10 | K36: =-Ires_pct*MAX(0,$C$34)*K$10 | L36: =-Ires_pct*MAX(0,$C$34)*L$10 | ... AO36: =-Ires_pct*MAX(0,$C$34)*AO$10
A37: Flusso di cassa dopo IRES | B37: EUR | C37: =SUM(E37:AO37) | E37: =E34+E36 | F37: =F34+F36 | G37: =G34+G36 | H37: =H34+H36 | I37: =I34+I36 | J37: =J34+J36 | K37: =K34+K36 | L37: =L34+L36 | ... AO37: =AO34+AO36
A39: Club deal: flussi per socio
A40: Investitori | B40: EUR | C40: =SUM(E40:AO40) | E40: =-MIN(0,E37)*-(1-Sponsor_cap)+Outputs!$C$40*E$10 | F40: =-MIN(0,F37)*-(1-Sponsor_cap)+Outputs!$C$40*F$10 | G40: =-MIN(0,G37)*-(1-Sponsor_cap)+Outputs!$C$40*G$10 | H40: =-MIN(0,H37)*-(1-Sponsor_cap)+Outputs!$C$40*H$10 | I40: =-MIN(0,I37)*-(1-Sponsor_cap)+Outputs!$C$40*I$10 | J40: =-MIN(0,J37)*-(1-Sponsor_cap)+Outputs!$C$40*J$10 | K40: =-MIN(0,K37)*-(1-Sponsor_cap)+Outputs!$C$40*K$10 | L40: =-MIN(0,L37)*-(1-Sponsor_cap)+Outputs!$C$40*L$10 | ... AO40: =-MIN(0,AO37)*-(1-Sponsor_cap)+Outputs!$C$40*AO$10
A41: Promotore (QRE) | B41: EUR | C41: =SUM(E41:AO41) | E41: =-MIN(0,E37)*-Sponsor_cap+Outputs!$C$41*E$10 | F41: =-MIN(0,F37)*-Sponsor_cap+Outputs!$C$41*F$10 | G41: =-MIN(0,G37)*-Sponsor_cap+Outputs!$C$41*G$10 | H41: =-MIN(0,H37)*-Sponsor_cap+Outputs!$C$41*H$10 | I41: =-MIN(0,I37)*-Sponsor_cap+Outputs!$C$41*I$10 | J41: =-MIN(0,J37)*-Sponsor_cap+Outputs!$C$41*J$10 | K41: =-MIN(0,K37)*-Sponsor_cap+Outputs!$C$41*K$10 | L41: =-MIN(0,L37)*-Sponsor_cap+Outputs!$C$41*L$10 | ... AO41: =-MIN(0,AO37)*-Sponsor_cap+Outputs!$C$41*AO$10

Sheet Outputs
A1: Risultati
A3: Prezzo offerto | C3: =Prezzo
A4: Costo totale (prezzo, imposte, condominio, lavori, regolarizzazioni) | C4: =-(CF!$C$16+CF!$C$27)
A5: Prezzo di vendita netto | C5: =CF!$C$32
A6: Utile ante imposte | C6: =CF!$C$34
A7: Margine sul costo | C7: =C6/C4
A8: Capitale impegnato (picco di cassa) | C8: =-MIN(CF!$E$35:$AO$35)
A9: IRR annuo ante imposte | C9: =(1+IRR(CF!$E$34:$AO$34))^12-1
A10: Utile dopo IRES | C10: =CF!$C$37
A11: IRR annuo dopo IRES | C11: =(1+IRR(CF!$E$37:$AO$37))^12-1
A12: Multiplo del capitale dopo IRES | C12: =SUMIF(CF!$E$37:$AO$37,">0")/-SUMIF(CF!$E$37:$AO$37,"<0")
A13: Durata dell'operazione | C13: =MeseVendita
A15: PREZZO MASSIMO D'OFFERTA
A16: Costi fissi non legati al prezzo (positivi) | C16: =-CF!$C$27
A17: Prezzo massimo per margine obiettivo | C17: =(C5/(1+Margine_obj)-C16)/(1+Registro_pct)
A18: VAN al tasso obiettivo dei flussi non legati al prezzo | C18: =SUMPRODUCT(CF!$E$27:$AO$27+CF!$E$32:$AO$32,(1+TassoMese)^-CF!$E$3:$AO$3)
A19: VAN per 1 EUR di prezzo offerto | C19: =SUMPRODUCT(CF!$E$16:$AO$16,(1+TassoMese)^-CF!$E$3:$AO$3)/Prezzo
A20: Prezzo massimo per IRR obiettivo (ante imposte) | C20: =-C18/C19
A21: Prezzo massimo d'offerta (il piu' basso dei due) | C21: =MIN(C17,C20)
A22: Vincolo che lega | C22: =IF(C17<=C20,"margine","IRR")
A23: Rispetto all'offerta minima (84.600) | C23: =C21/OffertaMinima-1
A24: Aggiudicazione attesa (base x moltiplicatore) | C24: =PrezzoBase*Moltiplicatore
A25: Margine di sicurezza: prezzo massimo meno aggiudicazione attesa | C25: =C21-C24
A27: PUNTO DI PAREGGIO SUL VALORE DI USCITA (al prezzo offerto)
A28: Uscita per margine obiettivo | C28: =(C4*(1+Margine_obj)/(1-Vendita_pct)-Accessori)/MqComm
A29: Uscita per utile zero | C29: =(C4/(1-Vendita_pct)-Accessori)/MqComm
A30: Uscita usata nel caso attivo | C30: =UscitaMq
A31: Riscontro: valore della perizia / superficie commerciale | C31: =ValorePerizia/MqComm
A33: VERIFICA DEI PREZZI MASSIMI (ricalcolo indipendente)
A34: Margine al prezzo massimo per margine | C34: =(C5-(C17*(1+Registro_pct)+C16))/(C17*(1+Registro_pct)+C16)
A35: VAN al prezzo massimo per IRR (deve essere circa 0) | C35: =C18+C19*C20
A37: CLUB DEAL (alla vendita, dopo IRES)
A38: Capitale totale versato | C38: =-SUMIF(CF!$E$37:$AO$37,"<0")
A39: Preferenziale maturato investitori (semplice) | C39: =C38*(1-Sponsor_cap)*Pref_pct*MeseVendita/12
A40: Distribuzione agli investitori | C40: =C44*(1-Sponsor_cap)+C45+C46*(1-Sponsor_split)
A41: Distribuzione al promotore | C41: =C47-C40
A42: IRR investitori | C42: =(1+IRR(CF!$E$40:$AO$40))^12-1
A43: IRR promotore | C43: =(1+IRR(CF!$E$41:$AO$41))^12-1
A44: Capitale restituito (pro quota; una perdita si ripartisce pro quota) | C44: =MIN(C47,C38)
A45: Preferenziale pagato | C45: =MIN(C47-C44,C39)
...

Sheet Checks
A1: Controlli (1 = problema)
A3: Le famiglie di costo e vendita sommano al flusso di cassa | B3: =IFERROR(1*(ABS(CF!$C$16+CF!$C$27+CF!$C$32-CF!$C$34)>0.5),1)
A4: La vendita cade dentro la griglia di 36 mesi | B4: =IFERROR(1*(MeseVendita>MesiGriglia),1)
A5: Il calendario e' in ordine (saldo < decreto < lavori < vendita) | B5: =IFERROR(1*NOT(AND(MeseSaldo<MeseDecreto,MeseDecreto<MeseLavoriIni,MeseLavoriFine<MeseVendita)),1)
A6: Selettore dello scenario valido | B6: =IFERROR(1*(OR(Scenario<1,Scenario>NumScenari,Scenario<>INT(Scenario))),1)
A7: Il prezzo massimo per margine restituisce il margine obiettivo | B7: =IFERROR(1*(ABS(Outputs!C34-Margine_obj)>0.0001),1)
A8: Il prezzo massimo per IRR azzera il VAN | B8: =IFERROR(1*(ABS(Outputs!C35)>1),1)
A9: I flussi dei soci sommano al flusso dopo IRES | B9: =IFERROR(1*(ABS(CF!C40+CF!C41-CF!$C$37)>1),1)
A10: IRR ante imposte calcolato (non errore) | B10: =IFERROR(1*NOT(ISNUMBER(Outputs!C9)),1)
A12: Warnings
A13: Prezzo offerto sopra il prezzo massimo d'offerta | B13: =IFERROR(1*(Prezzo>Outputs!C21),1)
A14: Margine sotto la soglia QRE | B14: =IFERROR(1*(Outputs!C7<Margine_obj),1)
A15: IRR dopo IRES sotto la soglia QRE | B15: =IFERROR(1*(Outputs!C11<Irr_obj),1)
A16: Occupato da terzi senza titolo: liberazione affidata al custode (ordine del 29/05/2026) | B16: 1
A17: Moltiplicatore 1,20 calibrato su aste di Milano, non dell'hinterland | B17: 1
A18: Cauzione: percentuale da verificare nell'avviso | B18: 1
A19: Aliquota di registro e trattamento IVA da confermare col parere fiscale | B19: 1
A21: Errori totali | B21: =SUM(B3:B10)
A22: Avvisi totali | B22: =SUM(B13:B19)
